Workbook

Sheet DATA
A1: Row ID | B1: Order ID | C1: Order Date | D1: Ship Date | E1: Ship Mode | F1: Customer ID | G1: Customer Name | H1: Segment | I1: Country | J1: City | K1: State | L1: Postal Code | M1: Region | N1: Product ID | O1: Category | P1: Sub-Category | Q1: Product Name | R1: Sales | S1: Quantity | T1: Discount | U1: Profit
A2: 0 1 1 2 2 3 3 4 4 5 ... 9989 9990 9990 9991 9991 9992 9992 9993 9993 9994 Name: Row ID, Length: 9994, dtype: int64 | B2: CA-2016-152156 | C2: 42593 | D2: 42685 | E2: Second Class | F2: CG-12520 | G2: Claire Gute | H2: Consumer | I2: United States | J2: Henderson | K2: Kentucky | L2: 0 42420 1 42420 2 90036 3 33311 4 33311 ... 9989 33180 9990 92627 9991 92627 9992 92627 9993 92683 Name: Postal Code, Length: 9994, dtype: int64 | M2: South | N2: FUR-BO-10001798 | O2: Furniture | P2: Bookcases | Q2: Bush Somerset Collection Bookcase | R2: 261.96 | S2: 2 | T2: 0 | U2: 41.9136 | V2: =IF(OR(C2 = "", D2 = ""), "", DATEDIF(C2, D2, "D")) | Z2: {=_xlfn.UNIQUE(DATA!P:P)}
A3: 0 1 1 2 2 3 3 4 4 5 ... 9989 9990 9990 9991 9991 9992 9992 9993 9993 9994 Name: Row ID, Length: 9994, dtype: int64 | B3: CA-2016-152156 | C3: 42593 | D3: 42685 | E3: Second Class | F3: CG-12520 | G3: Claire Gute | H3: Consumer | I3: United States | J3: Henderson | K3: Kentucky | L3: 0 42420 1 42420 2 90036 3 33311 4 33311 ... 9989 33180 9990 92627 9991 92627 9992 92627 9993 92683 Name: Postal Code, Length: 9994, dtype: int64 | M3: South | N3: FUR-CH-10000454 | O3: Furniture | P3: Chairs | Q3: Hon Deluxe Fabric Upholstered Stacking Chairs, Rounded Back | R3: 731.94 | S3: 3 | T3: 0 | U3: 219.582 | V3: =IF(OR(C3 = "", D3 = ""), "", DATEDIF(C3, D3, "D")) | AA3: =SUMIF(DATA!P:P,DATA!Z3,DATA!U:U) | AC3: {=_xlfn.SORT(DATA!Z3:AA19,2,-1)}
A4: 0 1 1 2 2 3 3 4 4 5 ... 9989 9990 9990 9991 9991 9992 9992 9993 9993 9994 Name: Row ID, Length: 9994, dtype: int64 | B4: CA-2016-138688 | C4: 42710 | E4: Second Class | F4: DV-13045 | G4: Darrin Van Huff | H4: Corporate | I4: United States | J4: Los Angeles | K4: California | L4: 0 42420 1 42420 2 90036 3 33311 4 33311 ... 9989 33180 9990 92627 9991 92627 9992 92627 9993 92683 Name: Postal Code, Length: 9994, dtype: int64 | M4: West | N4: OFF-LA-10000240 | O4: Office Supplies | P4: Labels | Q4: Self-Adhesive Address Labels for Typewriters by Universal | R4: 14.62 | S4: 2 | T4: 0 | U4: 6.8714 | V4: =IF(OR(C4 = "", D4 = ""), "", DATEDIF(C4, D4, "D")) | AA4: =SUMIF(DATA!P:P,DATA!Z4,DATA!U:U)
A5: 0 1 1 2 2 3 3 4 4 5 ... 9989 9990 9990 9991 9991 9992 9992 9993 9993 9994 Name: Row ID, Length: 9994, dtype: int64 | B5: US-2015-108966 | C5: 42318 | E5: Standard Class | F5: SO-20335 | G5: Sean O'Donnell | H5: Consumer | I5: United States | J5: Fort Lauderdale | K5: Florida | L5: 0 42420 1 42420 2 90036 3 33311 4 33311 ... 9989 33180 9990 92627 9991 92627 9992 92627 9993 92683 Name: Postal Code, Length: 9994, dtype: int64 | M5: South | N5: FUR-TA-10000577 | O5: Furniture | P5: Tables | Q5: Bretford CR4500 Series Slim Rectangular Table | R5: 957.5775 | S5: 5 | T5: 0.45 | U5: -383.031 | V5: =IF(OR(C5 = "", D5 = ""), "", DATEDIF(C5, D5, "D")) | AA5: =SUMIF(DATA!P:P,DATA!Z5,DATA!U:U)
A6: 0 1 1 2 2 3 3 4 4 5 ... 9989 9990 9990 9991 9991 9992 9992 9993 9993 9994 Name: Row ID, Length: 9994, dtype: int64 | B6: US-2015-108966 | C6: 42318 | E6: Standard Class | F6: SO-20335 | G6: Sean O'Donnell | H6: Consumer | I6: United States | J6: Fort Lauderdale | K6: Florida | L6: 0 42420 1 42420 2 90036 3 33311 4 33311 ... 9989 33180 9990 92627 9991 92627 9992 92627 9993 92683 Name: Postal Code, Length: 9994, dtype: int64 | M6: South | N6: OFF-ST-10000760 | O6: Office Supplies | P6: Storage | Q6: Eldon Fold 'N Roll Cart System | R6: 22.368 | S6: 2 | T6: 0.2 | U6: 2.5164 | V6: =IF(OR(C6 = "", D6 = ""), "", DATEDIF(C6, D6, "D")) | AA6: =SUMIF(DATA!P:P,DATA!Z6,DATA!U:U)
A7: 0 1 1 2 2 3 3 4 4 5 ... 9989 9990 9990 9991 9991 9992 9992 9993 9993 9994 Name: Row ID, Length: 9994, dtype: int64 | B7: CA-2014-115812 | C7: 41888 | E7: Standard Class | F7: BH-11710 | G7: Brosina Hoffman | H7: Consumer | I7: United States | J7: Los Angeles | K7: California | L7: 0 42420 1 42420 2 90036 3 33311 4 33311 ... 9989 33180 9990 92627 9991 92627 9992 92627 9993 92683 Name: Postal Code, Length: 9994, dtype: int64 | M7: West | N7: FUR-FU-10001487 | O7: Furniture | P7: Furnishings | Q7: Eldon Expressions Wood and Plastic Desk Accessories, Cherry Wood | R7: 48.86 | S7: 7 | T7: 0 | U7: 14.1694 | V7: =IF(OR(C7 = "", D7 = ""), "", DATEDIF(C7, D7, "D")) | AA7: =SUMIF(DATA!P:P,DATA!Z7,DATA!U:U)
A8: 0 1 1 2 2 3 3 4 4 5 ... 9989 9990 9990 9991 9991 9992 9992 9993 9993 9994 Name: Row ID, Length: 9994, dtype: int64 | B8: CA-2014-115812 | C8: 41888 | E8: Standard Class | F8: BH-11710 | G8: Brosina Hoffman | H8: Consumer | I8: United States | J8: Los Angeles | K8: California | L8: 0 42420 1 42420 2 90036 3 33311 4 33311 ... 9989 33180 9990 92627 9991 92627 9992 92627 9993 92683 Name: Postal Code, Length: 9994, dtype: int64 | M8: West | N8: OFF-AR-10002833 | O8: Office Supplies | P8: Art | Q8: Newell 322 | R8: 7.28 | S8: 4 | T8: 0 | U8: 1.9656 | V8: =IF(OR(C8 = "", D8 = ""), "", DATEDIF(C8, D8, "D")) | AA8: =SUMIF(DATA!P:P,DATA!Z8,DATA!U:U)
A9: 0 1 1 2 2 3 3 4 4 5 ... 9989 9990 9990 9991 9991 9992 9992 9993 9993 9994 Name: Row ID, Length: 9994, dtype: int64 | B9: CA-2014-115812 | C9: 41888 | E9: Standard Class | F9: BH-11710 | G9: Brosina Hoffman | H9: Consumer | I9: United States | J9: Los Angeles | K9: California | L9: 0 42420 1 42420 2 90036 3 33311 4 33311 ... 9989 33180 9990 92627 9991 92627 9992 92627 9993 92683 Name: Postal Code, Length: 9994, dtype: int64 | M9: West | N9: TEC-PH-10002275 | O9: Technology | P9: Phones | Q9: Mitel 5320 IP Phone VoIP phone | R9: 907.152 | S9: 6 | T9: 0.2 | U9: 90.7152 | V9: =IF(OR(C9 = "", D9 = ""), "", DATEDIF(C9, D9, "D")) | AA9: =SUMIF(DATA!P:P,DATA!Z9,DATA!U:U)
A10: 0 1 1 2 2 3 3 4 4 5 ... 9989 9990 9990 9991 9991 9992 9992 9993 9993 9994 Name: Row ID, Length: 9994, dtype: int64 | B10: CA-2014-115812 | C10: 41888 | E10: Standard Class | F10: BH-11710 | G10: Brosina Hoffman | H10: Consumer | I10: United States | J10: Los Angeles | K10: California | L10: 0 42420 1 42420 2 90036 3 33311 4 33311 ... 9989 33180 9990 92627 9991 92627 9992 92627 9993 92683 Name: Postal Code, Length: 9994, dtype: int64 | M10: West | N10: OFF-BI-10003910 | O10: Office Supplies | P10: Binders | Q10: DXL Angle-View Binders with Locking Rings by Samsill | R10: 18.504 | S10: 3 | T10: 0.2 | U10: 5.7825 | V10: =IF(OR(C10 = "", D10 = ""), "", DATEDIF(C10, D10, "D")) | AA10: =SUMIF(DATA!P:P,DATA!Z10,DATA!U:U)
A11: 0 1 1 2 2 3 3 4 4 5 ... 9989 9990 9990 9991 9991 9992 9992 9993 9993 9994 Name: Row ID, Length: 9994, dtype: int64 | B11: CA-2014-115812 | C11: 41888 | E11: Standard Class | F11: BH-11710 | G11: Brosina Hoffman | H11: Consumer | I11: United States | J11: Los Angeles | K11: California | L11: 0 42420 1 42420 2 90036 3 33311 4 33311 ... 9989 33180 9990 92627 9991 92627 9992 92627 9993 92683 Name: Postal Code, Length: 9994, dtype: int64 | M11: West | N11: OFF-AP-10002892 | O11: Office Supplies | P11: Appliances | Q11: Belkin F5C206VTEL 6 Outlet Surge | R11: 114.9 | S11: 5 | T11: 0 | U11: 34.47 | V11: =IF(OR(C11 = "", D11 = ""), "", DATEDIF(C11, D11, "D")) | AA11: =SUMIF(DATA!P:P,DATA!Z11,DATA!U:U)
A12: 0 1 1 2 2 3 3 4 4 5 ... 9989 9990 9990 9991 9991 9992 9992 9993 9993 9994 Name: Row ID, Length: 9994, dtype: int64 | B12: CA-2014-115812 | C12: 41888 | E12: Standard Class | F12: BH-11710 | G12: Brosina Hoffman | H12: Consumer | I12: United States | J12: Los Angeles | K12: California | L12: 0 42420 1 42420 2 90036 3 33311 4 33311 ... 9989 33180 9990 92627 9991 92627 9992 92627 9993 92683 Name: Postal Code, Length: 9994, dtype: int64 | M12: West | N12: FUR-TA-10001539 | O12: Furniture | P12: Tables | Q12: Chromcraft Rectangular Conference Tables | R12: 1706.184 | S12: 9 | T12: 0.2 | U12: 85.3092 | V12: =IF(OR(C12 = "", D12 = ""), "", DATEDIF(C12, D12, "D")) | AA12: =SUMIF(DATA!P:P,DATA!Z12,DATA!U:U)
A13: 0 1 1 2 2 3 3 4 4 5 ... 9989 9990 9990 9991 9991 9992 9992 9993 9993 9994 Name: Row ID, Length: 9994, dtype: int64 | B13: CA-2014-115812 | C13: 41888 | E13: Standard Class | F13: BH-11710 | G13: Brosina Hoffman | H13: Consumer | I13: United States | J13: Los Angeles | K13: California | L13: 0 42420 1 42420 2 90036 3 33311 4 33311 ... 9989 33180 9990 92627 9991 92627 9992 92627 9993 92683 Name: Postal Code, Length: 9994, dtype: int64 | M13: West | N13: TEC-PH-10002033 | O13: Technology | P13: Phones | Q13: Konftel 250 Conference phone - Charcoal black | R13: 911.424 | S13: 4 | T13: 0.2 | U13: 68.3568 | V13: =IF(OR(C13 = "", D13 = ""), "", DATEDIF(C13, D13, "D")) | AA13: =SUMIF(DATA!P:P,DATA!Z13,DATA!U:U)
A14: 0 1 1 2 2 3 3 4 4 5 ... 9989 9990 9990 9991 9991 9992 9992 9993 9993 9994 Name: Row ID, Length: 9994, dtype: int64 | B14: CA-2017-114412 | E14: Standard Class | F14: AA-10480 | G14: Andrew Allen | H14: Consumer | I14: United States | J14: Concord | K14: North Carolina | L14: 0 42420 1 42420 2 90036 3 33311 4 33311 ... 9989 33180 9990 92627 9991 92627 9992 92627 9993 92683 Name: Postal Code, Length: 9994, dtype: int64 | M14: South | N14: OFF-PA-10002365 | O14: Office Supplies | P14: Paper | Q14: Xerox 1967 | R14: 15.552 | S14: 3 | T14: 0.2 | U14: 5.4432 | V14: =IF(OR(C14 = "", D14 = ""), "", DATEDIF(C14, D14, "D")) | AA14: =SUMIF(DATA!P:P,DATA!Z14,DATA!U:U)
A15: 0 1 1 2 2 3 3 4 4 5 ... 9989 9990 9990 9991 9991 9992 9992 9993 9993 9994 Name: Row ID, Length: 9994, dtype: int64 | B15: CA-2016-161389 | C15: 42502 | D15: 42655 | E15: Standard Class | F15: IM-15070 | G15: Irene Maddox | H15: Consumer | I15: United States | J15: Seattle | K15: Washington | L15: 0 42420 1 42420 2 90036 3 33311 4 33311 ... 9989 33180 9990 92627 9991 92627 9992 92627 9993 92683 Name: Postal Code, Length: 9994, dtype: int64 | M15: West | N15: OFF-BI-10003656 | O15: Office Supplies | P15: Binders | Q15: Fellowes PB200 Plastic Comb Binding Machine | R15: 407.976 | S15: 3 | T15: 0.2 | U15: 132.5922 | V15: =IF(OR(C15 = "", D15 = ""), "", DATEDIF(C15, D15, "D")) | AA15: =SUMIF(DATA!P:P,DATA!Z15,DATA!U:U)
A16: 0 1 1 2 2 3 3 4 4 5 ... 9989 9990 9990 9991 9991 9992 9992 9993 9993 9994 Name: Row ID, Length: 9994, dtype: int64 | B16: US-2015-118983 | E16: Standard Class | F16: HP-14815 | G16: Harold Pawlan | H16: Home Office | I16: United States | J16: Fort Worth | K16: Texas | L16: 0 42420 1 42420 2 90036 3 33311 4 33311 ... 9989 33180 9990 92627 9991 92627 9992 92627 9993 92683 Name: Postal Code, Length: 9994, dtype: int64 | M16: Central | N16: OFF-AP-10002311 | O16: Office Supplies | P16: Appliances | Q16: Holmes Replacement Filter for HEPA Air Cleaner, Very Large Room, HEPA Filter | R16: 68.81 | S16: 5 | T16: 0.8 | U16: -123.858 | V16: =IF(OR(C16 = "", D16 = ""), "", DATEDIF(C16, D16, "D")) | AA16: =SUMIF(DATA!P:P,DATA!Z16,DATA!U:U)
A17: 0 1 1 2 2 3 3 4 4 5 ... 9989 9990 9990 9991 9991 9992 9992 9993 9993 9994 Name: Row ID, Length: 9994, dtype: int64 | B17: US-2015-118983 | E17: Standard Class | F17: HP-14815 | G17: Harold Pawlan | H17: Home Office | I17: United States | J17: Fort Worth | K17: Texas | L17: 0 42420 1 42420 2 90036 3 33311 4 33311 ... 9989 33180 9990 92627 9991 92627 9992 92627 9993 92683 Name: Postal Code, Length: 9994, dtype: int64 | M17: Central | N17: OFF-BI-10000756 | O17: Office Supplies | P17: Binders | Q17: Storex DuraTech Recycled Plastic Frosted Binders | R17: 2.544 | S17: 3 | T17: 0.8 | U17: -3.816 | V17: =IF(OR(C17 = "", D17 = ""), "", DATEDIF(C17, D17, "D")) | AA17: =SUMIF(DATA!P:P,DATA!Z17,DATA!U:U)
A18: 0 1 1 2 2 3 3 4 4 5 ... 9989 9990 9990 9991 9991 9992 9992 9993 9993 9994 Name: Row ID, Length: 9994, dtype: int64 | B18: CA-2014-105893 | C18: 41954 | E18: Standard Class | F18: PK-19075 | G18: Pete Kriz | H18: Consumer | I18: United States | J18: Madison | K18: Wisconsin | L18: 0 42420 1 42420 2 90036 3 33311 4 33311 ... 9989 33180 9990 92627 9991 92627 9992 92627 9993 92683 Name: Postal Code, Length: 9994, dtype: int64 | M18: Central | N18: OFF-ST-10004186 | O18: Office Supplies | P18: Storage | Q18: Stur-D-Stor Shelving, Vertical 5-Shelf: 72"H x 36"W x 18 1/2"D | R18: 665.88 | S18: 6 | T18: 0 | U18: 13.3176 | V18: =IF(OR(C18 = "", D18 = ""), "", DATEDIF(C18, D18, "D")) | AA18: =SUMIF(DATA!P:P,DATA!Z18,DATA!U:U)
A19: 0 1 1 2 2 3 3 4 4 5 ... 9989 9990 9990 9991 9991 9992 9992 9993 9993 9994 Name: Row ID, Length: 9994, dtype: int64 | B19: CA-2014-167164 | E19: Second Class | F19: AG-10270 | G19: Alejandro Grove | H19: Consumer | I19: United States | J19: West Jordan | K19: Utah | L19: 0 42420 1 42420 2 90036 3 33311 4 33311 ... 9989 33180 9990 92627 9991 92627 9992 92627 9993 92683 Name: Postal Code, Length: 9994, dtype: int64 | M19: West | N19: OFF-ST-10000107 | O19: Office Supplies | P19: Storage | Q19: Fellowes Super Stor/Drawer | R19: 55.5 | S19: 2 | T19: 0 | U19: 9.99 | V19: =IF(OR(C19 = "", D19 = ""), "", DATEDIF(C19, D19, "D")) | AA19: =SUMIF(DATA!P:P,DATA!Z19,DATA!U:U)
A20: 0 1 1 2 2 3 3 4 4 5 ... 9989 9990 9990 9991 9991 9992 9992 9993 9993 9994 Name: Row ID, Length: 9994, dtype: int64 | B20: CA-2014-143336 | D20: 41648 | E20: Second Class | F20: ZD-21925 | G20: Zuschuss Donatelli | H20: Consumer | I20: United States | J20: San Francisco | K20: California | L20: 0 42420 1 42420 2 90036 3 33311 4 33311 ... 9989 33180 9990 92627 9991 92627 9992 92627 9993 92683 Name: Postal Code, Length: 9994, dtype: int64 | M20: West | N20: OFF-AR-10003056 | O20: Office Supplies | P20: Art | Q20: Newell 341 | R20: 8.56 | S20: 2 | T20: 0 | U20: 2.4824 | V20: =IF(OR(C20 = "", D20 = ""), "", DATEDIF(C20, D20, "D"))
A21: 0 1 1 2 2 3 3 4 4 5 ... 9989 9990 9990 9991 9991 9992 9992 9993 9993 9994 Name: Row ID, Length: 9994, dtype: int64 | B21: CA-2014-143336 | D21: 41648 | E21: Second Class | F21: ZD-21925 | G21: Zuschuss Donatelli | H21: Consumer | I21: United States | J21: San Francisco | K21: California | L21: 0 42420 1 42420 2 90036 3 33311 4 33311 ... 9989 33180 9990 92627 9991 92627 9992 92627 9993 92683 Name: Postal Code, Length: 9994, dtype: int64 | M21: West | N21: TEC-PH-10001949 | O21: Technology | P21: Phones | Q21: Cisco SPA 501G IP Phone | R21: 213.48 | S21: 3 | T21: 0.2 | U21: 16.011 | V21: =IF(OR(C21 = "", D21 = ""), "", DATEDIF(C21, D21, "D"))
A22: 0 1 1 2 2 3 3 4 4 5 ... 9989 9990 9990 9991 9991 9992 9992 9993 9993 9994 Name: Row ID, Length: 9994, dtype: int64 | B22: CA-2014-143336 | D22: 41648 | E22: Second Class | F22: ZD-21925 | G22: Zuschuss Donatelli | H22: Consumer | I22: United States | J22: San Francisco | K22: California | L22: 0 42420 1 42420 2 90036 3 33311 4 33311 ... 9989 33180 9990 92627 9991 92627 9992 92627 9993 92683 Name: Postal Code, Length: 9994, dtype: int64 | M22: West | N22: OFF-BI-10002215 | O22: Office Supplies | P22: Binders | Q22: Wilson Jones Hanging View Binder, White, 1" | R22: 22.72 | S22: 4 | T22: 0.2 | U22: 7.384 | V22: =IF(OR(C22 = "", D22 = ""), "", DATEDIF(C22, D22, "D"))
A23: 0 1 1 2 2 3 3 4 4 5 ... 9989 9990 9990 9991 9991 9992 9992 9993 9993 9994 Name: Row ID, Length: 9994, dtype: int64 | B23: CA-2016-137330 | C23: 42625 | E23: Standard Class | F23: KB-16585 | G23: Ken Black | H23: Corporate | I23: United States | J23: Fremont | K23: Nebraska | L23: 0 42420 1 42420 2 90036 3 33311 4 33311 ... 9989 33180 9990 92627 9991 92627 9992 92627 9993 92683 Name: Postal Code, Length: 9994, dtype: int64 | M23: Central | N23: OFF-AR-10000246 | O23: Office Supplies | P23: Art | Q23: Newell 318 | R23: 19.46 | S23: 7 | T23: 0 | U23: 5.0596 | V23: =IF(OR(C23 = "", D23 = ""), "", DATEDIF(C23, D23, "D"))
A24: 0 1 1 2 2 3 3 4 4 5 ... 9989 9990 9990 9991 9991 9992 9992 9993 9993 9994 Name: Row ID, Length: 9994, dtype: int64 | B24: CA-2016-137330 | C24: 42625 | E24: Standard Class | F24: KB-16585 | G24: Ken Black | H24: Corporate | I24: United States | J24: Fremont | K24: Nebraska | L24: 0 42420 1 42420 2 90036 3 33311 4 33311 ... 9989 33180 9990 92627 9991 92627 9992 92627 9993 92683 Name: Postal Code, Length: 9994, dtype: int64 | M24: Central | N24: OFF-AP-10001492 | O24: Office Supplies | P24: Appliances | Q24: Acco Six-Outlet Power Strip, 4' Cord Length | R24: 60.34 | S24: 7 | T24: 0 | U24: 15.6884 | V24: =IF(OR(C24 = "", D24 = ""), "", DATEDIF(C24, D24, "D"))
A25: 0 1 1 2 2 3 3 4 4 5 ... 9989 9990 9990 9991 9991 9992 9992 9993 9993 9994 Name: Row ID, Length: 9994, dtype: int64 | B25: US-2017-156909 | E25: Second Class | F25: SF-20065 | G25: Sandra Flanagan | H25: Consumer | I25: United States | J25: Philadelphia | K25: Pennsylvania | L25: 0 42420 1 42420 2 90036 3 33311 4 33311 ... 9989 33180 9990 92627 9991 92627 9992 92627 9993 92683 Name: Postal Code, Length: 9994, dtype: int64 | M25: East | N25: FUR-CH-10002774 | O25: Furniture | P25: Chairs | Q25: Global Deluxe Stacking Chair, Gray | R25: 71.372 | S25: 2 | T25: 0.3 | U25: -1.0196 | V25: =IF(OR(C25 = "", D25 = ""), "", DATEDIF(C25, D25, "D")) | Z25: {=_xlfn.UNIQUE(DATA!O:O)}
A26: 0 1 1 2 2 3 3 4 4 5 ... 9989 9990 9990 9991 9991 9992 9992 9993 9993 9994 Name: Row ID, Length: 9994, dtype: int64 | B26: CA-2015-106320 | E26: Standard Class | F26: EB-13870 | G26: Emily Burns | H26: Consumer | I26: United States | J26: Orem | K26: Utah | L26: 0 42420 1 42420 2 90036 3 33311 4 33311 ... 9989 33180 9990 92627 9991 92627 9992 92627 9993 92683 Name: Postal Code, Length: 9994, dtype: int64 | M26: West | N26: FUR-TA-10000577 | O26: Furniture | P26: Tables | Q26: Bretford CR4500 Series Slim Rectangular Table | R26: 1044.63 | S26: 3 | T26: 0 | U26: 240.2649 | V26: =IF(OR(C26 = "", D26 = ""), "", DATEDIF(C26, D26, "D")) | AA26: =SUMIF(DATA!O:O,DATA!Z26,DATA!R:R) | AB26: =AA26 / AA29
A27: 0 1 1 2 2 3 3 4 4 5 ... 9989 9990 9990 9991 9991 9992 9992 9993 9993 9994 Name: Row ID, Length: 9994, dtype: int64 | B27: CA-2016-121755 | E27: Second Class | F27: EH-13945 | G27: Eric Hoffmann | H27: Consumer | I27: United States | J27: Los Angeles | K27: California | L27: 0 42420 1 42420 2 90036 3 33311 4 33311 ... 9989 33180 9990 92627 9991 92627 9992 92627 9993 92683 Name: Postal Code, Length: 9994, dtype: int64 | M27: West | N27: OFF-BI-10001634 | O27: Office Supplies | P27: Binders | Q27: Wilson Jones Active Use Binders | R27: 11.648 | S27: 2 | T27: 0.2 | U27: 4.2224 | V27: =IF(OR(C27 = "", D27 = ""), "", DATEDIF(C27, D27, "D")) | AA27: =SUMIF(DATA!O:O,DATA!Z27,DATA!R:R) | AB27: =AA27 / AA29
A28: 0 1 1 2 2 3 3 4 4 5 ... 9989 9990 9990 9991 9991 9992 9992 9993 9993 9994 Name: Row ID, Length: 9994, dtype: int64 | B28: CA-2016-121755 | E28: Second Class | F28: EH-13945 | G28: Eric Hoffmann | H28: Consumer | I28: United States | J28: Los Angeles | K28: California | L28: 0 42420 1 42420 2 90036 3 33311 4 33311 ... 9989 33180 9990 92627 9991 92627 9992 92627 9993 92683 Name: Postal Code, Length: 9994, dtype: int64 | M28: West | N28: TEC-AC-10003027 | O28: Technology | P28: Accessories | Q28: Imation 8GB Mini TravelDrive USB 2.0 Flash Drive | R28: 90.57 | S28: 3 | T28: 0 | U28: 11.7741 | V28: =IF(OR(C28 = "", D28 = ""), "", DATEDIF(C28, D28, "D")) | AA28: =SUMIF(DATA!O:O,DATA!Z28,DATA!R:R) | AB28: =AA28 / AA29
A29: 0 1 1 2 2 3 3 4 4 5 ... 9989 9990 9990 9991 9991 9992 9992 9993 9993 9994 Name: Row ID, Length: 9994, dtype: int64 | B29: US-2015-150630 | E29: Standard Class | F29: TB-21520 | G29: Tracy Blumstein | H29: Consumer | I29: United States | J29: Philadelphia | K29: Pennsylvania | L29: 0 42420 1 42420 2 90036 3 33311 4 33311 ... 9989 33180 9990 92627 9991 92627 9992 92627 9993 92683 Name: Postal Code, Length: 9994, dtype: int64 | M29: East | N29: FUR-BO-10004834 | O29: Furniture | P29: Bookcases | Q29: Riverside Palais Royal Lawyers Bookcase, Royale Cherry Finish | R29: 3083.43 | S29: 7 | T29: 0.5 | U29: -1665.0522 | V29: =IF(OR(C29 = "", D29 = ""), "", DATEDIF(C29, D29, "D")) | AA29: =SUM(AA26:AA28)
A30: 0 1 1 2 2 3 3 4 4 5 ... 9989 9990 9990 9991 9991 9992 9992 9993 9993 9994 Name: Row ID, Length: 9994, dtype: int64 | B30: US-2015-150630 | E30: Standard Class | F30: TB-21520 | G30: Tracy Blumstein | H30: Consumer | I30: United States | J30: Philadelphia | K30: Pennsylvania | L30: 0 42420 1 42420 2 90036 3 33311 4 33311 ... 9989 33180 9990 92627 9991 92627 9992 92627 9993 92683 Name: Postal Code, Length: 9994, dtype: int64 | M30: East | N30: OFF-BI-10000474 | O30: Office Supplies | P30: Binders | Q30: Avery Recycled Flexi-View Covers for Binding Systems | R30: 9.618 | S30: 2 | T30: 0.7 | U30: -7.0532 | V30: =IF(OR(C30 = "", D30 = ""), "", DATEDIF(C30, D30, "D"))
A31: 0 1 1 2 2 3 3 4 4 5 ... 9989 9990 9990 9991 9991 9992 9992 9993 9993 9994 Name: Row ID, Length: 9994, dtype: int64 | B31: US-2015-150630 | E31: Standard Class | F31: TB-21520 | G31: Tracy Blumstein | H31: Consumer | I31: United States | J31: Philadelphia | K31: Pennsylvania | L31: 0 42420 1 42420 2 90036 3 33311 4 33311 ... 9989 33180 9990 92627 9991 92627 9992 92627 9993 92683 Name: Postal Code, Length: 9994, dtype: int64 | M31: East | N31: FUR-FU-10004848 | O31: Furniture | P31: Furnishings | Q31: Howard Miller 13-3/4" Diameter Brushed Chrome Round Wall Clock | R31: 124.2 | S31: 3 | T31: 0.2 | U31: 15.525 | V31: =IF(OR(C31 = "", D31 = ""), "", DATEDIF(C31, D31, "D"))
A32: 0 1 1 2 2 3 3 4 4 5 ... 9989 9990 9990 9991 9991 9992 9992 9993 9993 9994 Name: Row ID, Length: 9994, dtype: int64 | B32: US-2015-150630 | E32: Standard Class | F32: TB-21520 | G32: Tracy Blumstein | H32: Consumer | I32: United States | J32: Philadelphia | K32: Pennsylvania | L32: 0 42420 1 42420 2 90036 3 33311 4 33311 ... 9989 33180 9990 92627 9991 92627 9992 92627 9993 92683 Name: Postal Code, Length: 9994, dtype: int64 | M32: East | N32: OFF-EN-10001509 | O32: Office Supplies | P32: Envelopes | Q32: Poly String Tie Envelopes | R32: 3.264 | S32: 2 | T32: 0.2 | U32: 1.1016 | V32: =IF(OR(C32 = "", D32 = ""), "", DATEDIF(C32, D32, "D"))
A33: 0 1 1 2 2 3 3 4 4 5 ... 9989 9990 9990 9991 9991 9992 9992 9993 9993 9994 Name: Row ID, Length: 9994, dtype: int64 | B33: US-2015-150630 | E33: Standard Class | F33: TB-21520 | G33: Tracy Blumstein | H33: Consumer | I33: United States | J33: Philadelphia | K33: Pennsylvania | L33: 0 42420 1 42420 2 90036 3 33311 4 33311 ... 9989 33180 9990 92627 9991 92627 9992 92627 9993 92683 Name: Postal Code, Length: 9994, dtype: int64 | M33: East | N33: OFF-AR-10004042 | O33: Office Supplies | P33: Art | Q33: BOSTON Model 1800 Electric Pencil Sharpeners, Putty/Woodgrain | R33: 86.304 | S33: 6 | T33: 0.2 | U33: 9.7092 | V33: =IF(OR(C33 = "", D33 = ""), "", DATEDIF(C33, D33, "D"))
A34: 0 1 1 2 2 3 3 4 4 5 ... 9989 9990 9990 9991 9991 9992 9992 9993 9993 9994 Name: Row ID, Length: 9994, dtype: int64 | B34: US-2015-150630 | E34: Standard Class | F34: TB-21520 | G34: Tracy Blumstein | H34: Consumer | I34: United States | J34: Philadelphia | K34: Pennsylvania | L34: 0 42420 1 42420 2 90036 3 33311 4 33311 ... 9989 33180 9990 92627 9991 92627 9992 92627 9993 92683 Name: Postal Code, Length: 9994, dtype: int64 | M34: East | N34: OFF-BI-10001525 | O34: Office Supplies | P34: Binders | Q34: Acco Pressboard Covers with Storage Hooks, 14 7/8" x 11", Executive Red | R34: 6.858 | S34: 6 | T34: 0.7 | U34: -5.715 | V34: =IF(OR(C34 = "", D34 = ""), "", DATEDIF(C34, D34, "D"))
A35: 0 1 1 2 2 3 3 4 4 5 ... 9989 9990 9990 9991 9991 9992 9992 9993 9993 9994 Name: Row ID, Length: 9994, dtype: int64 | B35: US-2015-150630 | E35: Standard Class | F35: TB-21520 | G35: Tracy Blumstein | H35: Consumer | I35: United States | J35: Philadelphia | K35: Pennsylvania | L35: 0 42420 1 42420 2 90036 3 33311 4 33311 ... 9989 33180 9990 92627 9991 92627 9992 92627 9993 92683 Name: Postal Code, Length: 9994, dtype: int64 | M35: East | N35: OFF-AR-10001683 | O35: Office Supplies | P35: Art | Q35: Lumber Crayons | R35: 15.76 | S35: 2 | T35: 0.2 | U35: 3.546 | V35: =IF(OR(C35 = "", D35 = ""), "", DATEDIF(C35, D35, "D"))
A36: 0 1 1 2 2 3 3 4 4 5 ... 9989 9990 9990 9991 9991 9992 9992 9993 9993 9994 Name: Row ID, Length: 9994, dtype: int64 | B36: CA-2017-107727 | E36: Second Class | F36: MA-17560 | G36: Matt Abelman | H36: Home Office | I36: United States | J36: Houston | K36: Texas | L36: 0 42420 1 42420 2 90036 3 33311 4 33311 ... 9989 33180 9990 92627 9991 92627 9992 92627 9993 92683 Name: Postal Code, Length: 9994, dtype: int64 | M36: Central | N36: OFF-PA-10000249 | O36: Office Supplies | P36: Paper | Q36: Easy-staple paper | R36: 29.472 | S36: 3 | T36: 0.2 | U36: 9.9468 | V36: =IF(OR(C36 = "", D36 = ""), "", DATEDIF(C36, D36, "D"))
A37: 0 1 1 2 2 3 3 4 4 5 ... 9989 9990 9990 9991 9991 9992 9992 9993 9993 9994 Name: Row ID, Length: 9994, dtype: int64 | B37: CA-2016-117590 | C37: 42594 | D37: 42655 | E37: First Class | F37: GH-14485 | G37: Gene Hale | H37: Corporate | I37: United States | J37: Richardson | K37: Texas | L37: 0 42420 1 42420 2 90036 3 33311 4 33311 ... 9989 33180 9990 92627 9991 92627 9992 92627 9993 92683 Name: Postal Code, Length: 9994, dtype: int64 | M37: Central | N37: TEC-PH-10004977 | O37: Technology | P37: Phones | Q37: GE 30524EE4 | R37: 1097.544 | S37: 7 | T37: 0.2 | U37: 123.4737 | V37: =IF(OR(C37 = "", D37 = ""), "", DATEDIF(C37, D37, "D"))
A38: 0 1 1 2 2 3 3 4 4 5 ... 9989 9990 9990 9991 9991 9992 9992 9993 9993 9994 Name: Row ID, Length: 9994, dtype: int64 | B38: CA-2016-117590 | C38: 42594 | D38: 42655 | E38: First Class | F38: GH-14485 | G38: Gene Hale | H38: Corporate | I38: United States | J38: Richardson | K38: Texas | L38: 0 42420 1 42420 2 90036 3 33311 4 33311 ... 9989 33180 9990 92627 9991 92627 9992 92627 9993 92683 Name: Postal Code, Length: 9994, dtype: int64 | M38: Central | N38: FUR-FU-10003664 | O38: Furniture | P38: Furnishings | Q38: Electrix Architect's Clamp-On Swing Arm Lamp, Black | R38: 190.92 | S38: 5 | T38: 0.6 | U38: -147.963 | V38: =IF(OR(C38 = "", D38 = ""), "", DATEDIF(C38, D38, "D"))
A39: 0 1 1 2 2 3 3 4 4 5 ... 9989 9990 9990 9991 9991 9992 9992 9993 9993 9994 Name: Row ID, Length: 9994, dtype: int64 | B39: CA-2015-117415 | E39: Standard Class | F39: SN-20710 | G39: Steve Nguyen | H39: Home Office | I39: United States | J39: Houston | K39: Texas | L39: 0 42420 1 42420 2 90036 3 33311 4 33311 ... 9989 33180 9990 92627 9991 92627 9992 92627 9993 92683 Name: Postal Code, Length: 9994, dtype: int64 | M39: Central | N39: OFF-EN-10002986 | O39: Office Supplies | P39: Envelopes | Q39: #10-4 1/8" x 9 1/2" Premium Diagonal Seam Envelopes | R39: 113.328 | S39: 9 | T39: 0.2 | U39: 35.415 | V39: =IF(OR(C39 = "", D39 = ""), "", DATEDIF(C39, D39, "D"))
A40: 0 1 1 2 2 3 3 4 4 5 ... 9989 9990 9990 9991 9991 9992 9992 9993 9993 9994 Name: Row ID, Length: 9994, dtype: int64 | B40: CA-2015-117415 | E40: Standard Class | F40: SN-20710 | G40: Steve Nguyen | H40: Home Office | I40: United States | J40: Houston | K40: Texas | L40: 0 42420 1 42420 2 90036 3 33311 4 33311 ... 9989 33180 9990 92627 9991 92627 9992 92627 9993 92683 Name: Postal Code, Length: 9994, dtype: int64 | M40: Central | N40: FUR-BO-10002545 | O40: Furniture | P40: Bookcases | Q40: Atlantic Metals Mobile 3-Shelf Bookcases, Custom Colors | R40: 532.3992 | S40: 3 | T40: 0.32 | U40: -46.9764 | V40: =IF(OR(C40 = "", D40 = ""), "", DATEDIF(C40, D40, "D"))
...

Sheet VISUALISATIONS
I1: Performances économique
B3: Chiffre d'affaires | F3: Profits | J3: Volume des ventes | O3: Temps de livraison moyen (en jours)
B4: =SUM(DATA!R:R) | F4: =SUM(DATA!U:U) | J4: =SUM(DATA!S:S) | O4: =ROUND(AVERAGE(DATA!V:V),1)
